<?xml version="1.0"?>
<robot xmlns:xacro="http://ros.org/wiki/xacro" name="kirigami_gripper">
  <!-- Color Table
  <material name="Kirigami_Silver">
    <color rgba="0.753 0.753 0.753 0.5"/>
  </material>
  <material name="Kirigami_Red">
    <color rgba="0.549 0.157 0.157 1.0"/>
  </material>
  <material name="PET_White">
    <color rgba="1.0 1.0 1.0 0.5"/>
  </material>
  <material name="PET_Gray">
    <color rgba="0.286 0.286 0.286 0.5"/>
  </material>
  -->
  <!--<xacro:include filename="$(find lite6)/urdf/kirigami_gripper.transmission.xacro" />
  <xacro:include filename="$(find lite6)/urdf/kirigami_gripper.gazebo.xacro" />-->

  <xacro:macro name="kirigami_gripper_urdf" params="prefix:='' attach_to:='' rpy:='0 0 0' xyz:='0 0 0' ">
  <xacro:unless value="${attach_to == ''}">
    <joint name="${prefix}kirigami_gripper_fix" type="fixed">
      <parent link="${attach_to}"/>
      <child link="${prefix}kirigami_gripper_base"/>
      <origin xyz="${xyz}" rpy="${rpy}"/>
    </joint>
  </xacro:unless>
  <link
    name="${prefix}kirigami_gripper_base">
    <inertial>
      <origin
        xyz="0.00276 0.0 0.046"
        rpy="0 0 0" />
      <mass
        value="0.295" />
      <inertia
        ixx="0.00081394"
        ixy="5.0000E-08"
        ixz="2.9410E-05"
        iyy="0.00081881"
        iyz="1.1000E-07"
        izz="0.00022262" />
    </inertial>
    <visual>
      <origin
        xyz="0 0 0"
        rpy="0 0 0" />
      <geometry>
        <mesh
          filename="package://lite6/meshes/visual/kirigami_gripper_base.STL" />
      </geometry>
      <material name="Kirigami_Red">
        <color rgba="0.549 0.157 0.157 1.0"/>
      </material>
    </visual>
    <collision>
      <origin
        xyz="0 0 0"
        rpy="0 0 0" />
      <geometry>
        <mesh
          filename="package://lite6/meshes/collision/kirigami_gripper_base_collision.STL" />
      </geometry>
    </collision>
  </link>

<!-- finger_1 -->
  <joint name="${prefix}finger1_joint" type="revolute">
    <origin
      xyz="0.026 -0.0075 0.141"
      rpy="-1.5708 3.1415 0" />
    <parent
      link="${prefix}kirigami_gripper_base" />
    <child
      link="${prefix}finger_1" />
    <axis
      xyz="0 0 1" />
    <limit
      lower="-0.48"
      upper="0.45"
      effort="2.5"
      velocity="1.0"/>
  </joint>
  <xacro:insert_transmission name="finger1_joint" />
  <link
    name="${prefix}finger_1">
    <inertial>
      <origin
        xyz="-0.014 0.0224 0.0075"
        rpy="0 0 0" />
      <mass
        value="0.001" />
      <inertia
        ixx="1.2000E-07"
        ixy="0.00000"
        ixz="0.00000"
        iyy="3.0000E-08"
        iyz="0.00000"
        izz="1.4000E-07" />
    </inertial>
    <visual>
      <origin
        xyz="0 0 0"
        rpy="0 0 0" />
      <geometry>
        <mesh
          filename="package://lite6/meshes/visual/finger_1.STL" />
      </geometry>
      <material name="PET_White">
        <color rgba="1.0 1.0 1.0 0.5"/>
      </material>
    </visual>
    <collision>
      <origin
        xyz="0 0 0"
        rpy="0 0 0" />
      <geometry>
        <mesh
          filename="package://lite6/meshes/collision/finger_1_collision.STL" />
      </geometry>
    </collision>
  </link>

<!-- finger_2 -->
  <joint name="${prefix}finger2_joint" type="revolute">
    <origin
      xyz="-0.012 -0.01444 0.141"
      rpy="1.5708 0 1.0472" />
    <parent
      link="${prefix}kirigami_gripper_base" />
    <child
      link="${prefix}finger_2" />
    <axis
      xyz="0 0 1" />
    <limit
      lower="-0.48"
      upper="0.45"
      effort="2.5"
      velocity="1.0"/>
    <mimic joint="finger1_joint" multiplier="1"/>
  </joint>
  <xacro:mimic_joint_plugin_gazebo name_prefix="${prefix}finger2_joint"
    following_joint="${prefix}finger1_joint" mimic_joint="${prefix}finger2_joint"
    has_pid="false" multiplier="1.0" max_effort="10.0" />
  <link
    name="${prefix}finger_2">
    <inertial>
      <origin
        xyz="-0.014 0.0224 0.0075"
        rpy="0 0 0" />
      <mass
        value="0.001" />
      <inertia
        ixx="1.2000E-07"
        ixy="0.00000"
        ixz="0.00000"
        iyy="3.0000E-08"
        iyz="0.00000"
        izz="1.4000E-07" />
    </inertial>
    <visual>
      <origin
        xyz="0 0 0"
        rpy="0 0 0" />
      <geometry>
        <mesh
          filename="package://lite6/meshes/visual/finger_2.STL" />
      </geometry>
      <material name="PET_White">
        <color rgba="1.0 1.0 1.0 0.5"/>
      </material>
    </visual>
    <collision>
      <origin
        xyz="0 0 0"
        rpy="0 0 0" />
      <geometry>
        <mesh
          filename="package://lite6/meshes/collision/finger_2_collision.STL" />
      </geometry>
    </collision>
  </link>

<!-- finger_3 -->
  <joint name="${prefix}finger3_joint" type="revolute">
    <origin
      xyz="0.001 0.02194 0.141"
      rpy="1.5708 0 -1.0472" />
    <parent
      link="${prefix}kirigami_gripper_base" />
    <child
      link="${prefix}finger_3" />
    <axis
      xyz="0 0 1" />
    <limit
      lower="-0.48"
      upper="0.45"
      effort="2.5"
      velocity="1.0"/>
    <mimic joint="finger1_joint" multiplier="1"/>
  </joint>
  <xacro:mimic_joint_plugin_gazebo name_prefix="${prefix}finger3_joint"
    following_joint="${prefix}finger1_joint" mimic_joint="${prefix}finger3_joint"
    has_pid="false" multiplier="1.0" max_effort="10.0" />
  <link
    name="${prefix}finger_3">
    <inertial>
      <origin
        xyz="-0.014 0.0224 0.0075"
        rpy="0 0 0" />
      <mass
        value="0.001" />
      <inertia
        ixx="1.2000E-07"
        ixy="0.00000"
        ixz="0.00000"
        iyy="3.0000E-08"
        iyz="0.00000"
        izz="1.4000E-07" />
    </inertial>
    <visual>
      <origin
        xyz="0 0 0"
        rpy="0 0 0" />
      <geometry>
        <mesh
          filename="package://lite6/meshes/visual/finger_3.STL" />
      </geometry>
      <material name="PET_White">
        <color rgba="1.0 1.0 1.0 0.5"/>
      </material>
    </visual>
    <collision>
      <origin
        xyz="0 0 0"
        rpy="0 0 0" />
      <geometry>
        <mesh
          filename="package://lite6/meshes/collision/finger_3_collision.STL" />
      </geometry>
    </collision>
  </link>

<!--link_tcp-->
  <link name="${prefix}link_tcp" />
  <joint
    name="${prefix}joint_tcp"
    type="fixed">
    <origin
      xyz="0 0 0.18675"
      rpy="0 0 0" />
    <parent
      link="${prefix}kirigami_gripper_base" />
    <child
      link="${prefix}link_tcp" />
  </joint>

<!--If you unlock the following link and joint,
    you can measure distance between center of gripper and finger tip of kirigami gripper-->

  <link name="${prefix}measure_finger1" >
    <inertial>
      <origin
        xyz="0 0 0.0075"
        rpy="0 0 0" />
      <mass
        value="0.00001" />
      <inertia
        ixx="0.00000"
        ixy="0.00000"
        ixz="0.00000"
        iyy="0.00000"
        iyz="0.00000"
        izz="0.00000" />
    </inertial>
    <!-- <visual>
      <origin
        xyz="0 0 0"
        rpy="0 0 0" />
      <geometry>
        <mesh
          filename="package://lite6/meshes/visual/measure_ball.STL" />
      </geometry>
      <material name="Transparent">
        <color rgba="1.0 1.0 1.0 0.0"/>
      </material>
    </visual>
    <collision>
      <origin
        xyz="0 0 0"
        rpy="0 0 0" />
      <geometry>
        <mesh
          filename="package://lite6/meshes/collision/measure_ball.STL" />
      </geometry>
    </collision> -->
  </link> 
  <joint
    name="${prefix}measure_joint1"
    type="revolute">
    <origin
      xyz="0 0.0455 0"
      rpy="0 0 0" />
    <axis
      xyz="0 0 1" />
    <limit
      lower="-0.48"
      upper="0.45"
      effort="5.0"
      velocity="1.0"/>
    <parent
      link="${prefix}finger_1" />
    <child
      link="${prefix}measure_finger1" />
    <mimic joint="finger1_joint" multiplier="1"/>
  </joint>
  <xacro:mimic_joint_plugin_gazebo name_prefix="${prefix}measure_joint1"
    following_joint="${prefix}finger1_joint" mimic_joint="${prefix}measure_joint1"
    has_pid="false" multiplier="1.0" max_effort="10" />

  </xacro:macro>

</robot>